[2025-07-26T09:11:15.424+0000] {scheduler_job_runner.py:1586} WARNING - Marking task instance <TaskInstance: retail_sales_etl_pipeline.extract_transform_load_data scheduled__2025-07-25T00:00:00+00:00 [queued]> stuck in queued as failed. If the task instance has available retries, it will be retried.
[2025-07-26T09:11:16.633+0000] {scheduler_job_runner.py:781} ERROR - Executor reports task instance <TaskInstance: retail_sales_etl_pipeline.extract_transform_load_data scheduled__2025-07-25T00:00:00+00:00 [queued]> finished (failed) although the task says it's queued. (Info: None) Was the task killed externally?
