[2025-07-26T09:32:41.345+0000] {scheduler_job_runner.py:1586} WARNING - Marking task instance <TaskInstance: retail_sales_etl_pipeline.extract_transform_load_data manual__2025-07-26T09:06:00.139242+00:00 [queued]> stuck in queued as failed. If the task instance has available retries, it will be retried.
[2025-07-26T09:32:42.468+0000] {scheduler_job_runner.py:781} ERROR - Executor reports task instance <TaskInstance: retail_sales_etl_pipeline.extract_transform_load_data manual__2025-07-26T09:06:00.139242+00:00 [queued]> finished (failed) although the task says it's queued. (Info: None) Was the task killed externally?
